10/23/2022 15:17:15 - INFO - __main__ - Distributed environment: NO
Num processes: 1
Process index: 0
Local process index: 0
Device: cuda
Mixed precision type: no

10/23/2022 15:17:15 - WARNING - datasets.builder - Using custom data configuration default-a1fa35a57715e192
10/23/2022 15:17:15 - WARNING - datasets.builder - Found cached dataset json (/home/eo41/.cache/huggingface/datasets/json/default-a1fa35a57715e192/0.0.0/e6070c77f18f01a5ad4551a8b7edfba20b8438b7cad4d94e6ad9378022ce4aab)
  0%|          | 0/2 [00:00<?, ?it/s]100%|██████████| 2/2 [00:00<00:00, 393.72it/s]
Traceback (most recent call last):
  File "/scratch/eo41/miniconda3/envs/llm/lib/python3.9/site-packages/transformers/configuration_utils.py", line 613, in _get_config_dict
    resolved_config_file = cached_file(
  File "/scratch/eo41/miniconda3/envs/llm/lib/python3.9/site-packages/transformers/utils/hub.py", line 409, in cached_file
    resolved_file = hf_hub_download(
  File "/scratch/eo41/miniconda3/envs/llm/lib/python3.9/site-packages/huggingface_hub/file_download.py", line 1022, in hf_hub_download
    cache_dir, repo_folder_name(repo_id=repo_id, repo_type=repo_type)
  File "/scratch/eo41/miniconda3/envs/llm/lib/python3.9/site-packages/huggingface_hub/utils/_validators.py", line 92, in _inner_fn
    validate_repo_id(arg_value)
  File "/scratch/eo41/miniconda3/envs/llm/lib/python3.9/site-packages/huggingface_hub/utils/_validators.py", line 136, in validate_repo_id
    raise HFValidationError(
huggingface_hub.utils._validators.HFValidationError: Repo id must be in the form 'repo_name' or 'namespace/repo_name': '/scratch/eo41/lm-recognition-memory/models/opt_2.7b_data_0_0.0003_1'. Use `repo_type` argument if needed.

During handling of the above exception, another exception occurred:

Traceback (most recent call last):
  File "/scratch/eo41/lm-recognition-memory/evaluate.py", line 275, in <module>
    main()
  File "/scratch/eo41/lm-recognition-memory/evaluate.py", line 143, in main
    config = AutoConfig.from_pretrained(args.model_name_or_path)
  File "/scratch/eo41/miniconda3/envs/llm/lib/python3.9/site-packages/transformers/models/auto/configuration_auto.py", line 770, in from_pretrained
    config_dict, unused_kwargs = PretrainedConfig.get_config_dict(pretrained_model_name_or_path, **kwargs)
  File "/scratch/eo41/miniconda3/envs/llm/lib/python3.9/site-packages/transformers/configuration_utils.py", line 558, in get_config_dict
    config_dict, kwargs = cls._get_config_dict(pretrained_model_name_or_path, **kwargs)
  File "/scratch/eo41/miniconda3/envs/llm/lib/python3.9/site-packages/transformers/configuration_utils.py", line 634, in _get_config_dict
    raise EnvironmentError(
OSError: Can't load the configuration of '/scratch/eo41/lm-recognition-memory/models/opt_2.7b_data_0_0.0003_1'. If you were trying to load it from 'https://huggingface.co/models', make sure you don't have a local directory with the same name. Otherwise, make sure '/scratch/eo41/lm-recognition-memory/models/opt_2.7b_data_0_0.0003_1' is the correct path to a directory containing a config.json file
Fatal error condition occurred in /opt/vcpkg/buildtrees/aws-c-io/src/9e6648842a-364b708815.clean/source/event_loop.c:72: aws_thread_launch(&cleanup_thread, s_event_loop_destroy_async_thread_fn, el_group, &thread_options) == AWS_OP_SUCCESS
Exiting Application
################################################################################
Stack trace:
################################################################################
/scratch/eo41/miniconda3/envs/llm/lib/python3.9/site-packages/pyarrow/libarrow.so.900(+0x200af06) [0x1529bbee6f06]
/scratch/eo41/miniconda3/envs/llm/lib/python3.9/site-packages/pyarrow/libarrow.so.900(+0x20028e5) [0x1529bbede8e5]
/scratch/eo41/miniconda3/envs/llm/lib/python3.9/site-packages/pyarrow/libarrow.so.900(+0x1f27e09) [0x1529bbe03e09]
/scratch/eo41/miniconda3/envs/llm/lib/python3.9/site-packages/pyarrow/libarrow.so.900(+0x200ba3d) [0x1529bbee7a3d]
/scratch/eo41/miniconda3/envs/llm/lib/python3.9/site-packages/pyarrow/libarrow.so.900(+0x1f25948) [0x1529bbe01948]
/scratch/eo41/miniconda3/envs/llm/lib/python3.9/site-packages/pyarrow/libarrow.so.900(+0x200ba3d) [0x1529bbee7a3d]
/scratch/eo41/miniconda3/envs/llm/lib/python3.9/site-packages/pyarrow/libarrow.so.900(+0x1ee0b46) [0x1529bbdbcb46]
/scratch/eo41/miniconda3/envs/llm/lib/python3.9/site-packages/pyarrow/libarrow.so.900(+0x194546a) [0x1529bb82146a]
/lib64/libc.so.6(+0x39b0c) [0x1529cbeaab0c]
/lib64/libc.so.6(on_exit+0) [0x1529cbeaac40]
/lib64/libc.so.6(__libc_start_main+0xfa) [0x1529cbe9449a]
python() [0x588fae]
/opt/slurm/data/slurmd/job26191633/slurm_script: line 23: 825357 Aborted                 (core dumped) python -u /scratch/eo41/lm-recognition-memory/evaluate.py --model_name_or_path /scratch/eo41/lm-recognition-memory/models/${SP} --seen_file "data/recognition-memory-experimental-data/seen_${EX}.json" --unseen_file "data/recognition-memory-experimental-data/unseen_${EX}.json" --per_device_eval_batch_size 1 --output_dir "evals/expt1" --save_prefix ${SP} --block_size 128 --overwrite_cache
10/23/2022 15:17:20 - INFO - __main__ - Distributed environment: NO
Num processes: 1
Process index: 0
Local process index: 0
Device: cuda
Mixed precision type: no

10/23/2022 15:17:20 - WARNING - datasets.builder - Using custom data configuration default-a1fa35a57715e192
10/23/2022 15:17:20 - WARNING - datasets.builder - Found cached dataset json (/home/eo41/.cache/huggingface/datasets/json/default-a1fa35a57715e192/0.0.0/e6070c77f18f01a5ad4551a8b7edfba20b8438b7cad4d94e6ad9378022ce4aab)
  0%|          | 0/2 [00:00<?, ?it/s]100%|██████████| 2/2 [00:00<00:00, 432.27it/s]
Traceback (most recent call last):
  File "/scratch/eo41/miniconda3/envs/llm/lib/python3.9/site-packages/transformers/configuration_utils.py", line 613, in _get_config_dict
    resolved_config_file = cached_file(
  File "/scratch/eo41/miniconda3/envs/llm/lib/python3.9/site-packages/transformers/utils/hub.py", line 409, in cached_file
    resolved_file = hf_hub_download(
  File "/scratch/eo41/miniconda3/envs/llm/lib/python3.9/site-packages/huggingface_hub/file_download.py", line 1022, in hf_hub_download
    cache_dir, repo_folder_name(repo_id=repo_id, repo_type=repo_type)
  File "/scratch/eo41/miniconda3/envs/llm/lib/python3.9/site-packages/huggingface_hub/utils/_validators.py", line 92, in _inner_fn
    validate_repo_id(arg_value)
  File "/scratch/eo41/miniconda3/envs/llm/lib/python3.9/site-packages/huggingface_hub/utils/_validators.py", line 136, in validate_repo_id
    raise HFValidationError(
huggingface_hub.utils._validators.HFValidationError: Repo id must be in the form 'repo_name' or 'namespace/repo_name': '/scratch/eo41/lm-recognition-memory/models/opt_2.7b_data_0_0.0003_2'. Use `repo_type` argument if needed.

During handling of the above exception, another exception occurred:

Traceback (most recent call last):
  File "/scratch/eo41/lm-recognition-memory/evaluate.py", line 275, in <module>
    main()
  File "/scratch/eo41/lm-recognition-memory/evaluate.py", line 143, in main
    config = AutoConfig.from_pretrained(args.model_name_or_path)
  File "/scratch/eo41/miniconda3/envs/llm/lib/python3.9/site-packages/transformers/models/auto/configuration_auto.py", line 770, in from_pretrained
    config_dict, unused_kwargs = PretrainedConfig.get_config_dict(pretrained_model_name_or_path, **kwargs)
  File "/scratch/eo41/miniconda3/envs/llm/lib/python3.9/site-packages/transformers/configuration_utils.py", line 558, in get_config_dict
    config_dict, kwargs = cls._get_config_dict(pretrained_model_name_or_path, **kwargs)
  File "/scratch/eo41/miniconda3/envs/llm/lib/python3.9/site-packages/transformers/configuration_utils.py", line 634, in _get_config_dict
    raise EnvironmentError(
OSError: Can't load the configuration of '/scratch/eo41/lm-recognition-memory/models/opt_2.7b_data_0_0.0003_2'. If you were trying to load it from 'https://huggingface.co/models', make sure you don't have a local directory with the same name. Otherwise, make sure '/scratch/eo41/lm-recognition-memory/models/opt_2.7b_data_0_0.0003_2' is the correct path to a directory containing a config.json file
Fatal error condition occurred in /opt/vcpkg/buildtrees/aws-c-io/src/9e6648842a-364b708815.clean/source/event_loop.c:72: aws_thread_launch(&cleanup_thread, s_event_loop_destroy_async_thread_fn, el_group, &thread_options) == AWS_OP_SUCCESS
Exiting Application
################################################################################
Stack trace:
################################################################################
/scratch/eo41/miniconda3/envs/llm/lib/python3.9/site-packages/pyarrow/libarrow.so.900(+0x200af06) [0x14e1cd1e2f06]
/scratch/eo41/miniconda3/envs/llm/lib/python3.9/site-packages/pyarrow/libarrow.so.900(+0x20028e5) [0x14e1cd1da8e5]
/scratch/eo41/miniconda3/envs/llm/lib/python3.9/site-packages/pyarrow/libarrow.so.900(+0x1f27e09) [0x14e1cd0ffe09]
/scratch/eo41/miniconda3/envs/llm/lib/python3.9/site-packages/pyarrow/libarrow.so.900(+0x200ba3d) [0x14e1cd1e3a3d]
/scratch/eo41/miniconda3/envs/llm/lib/python3.9/site-packages/pyarrow/libarrow.so.900(+0x1f25948) [0x14e1cd0fd948]
/scratch/eo41/miniconda3/envs/llm/lib/python3.9/site-packages/pyarrow/libarrow.so.900(+0x200ba3d) [0x14e1cd1e3a3d]
/scratch/eo41/miniconda3/envs/llm/lib/python3.9/site-packages/pyarrow/libarrow.so.900(+0x1ee0b46) [0x14e1cd0b8b46]
/scratch/eo41/miniconda3/envs/llm/lib/python3.9/site-packages/pyarrow/libarrow.so.900(+0x194546a) [0x14e1ccb1d46a]
/lib64/libc.so.6(+0x39b0c) [0x14e1dd1a6b0c]
/lib64/libc.so.6(on_exit+0) [0x14e1dd1a6c40]
/lib64/libc.so.6(__libc_start_main+0xfa) [0x14e1dd19049a]
python() [0x588fae]
